Workbook

Sheet Лист1
A1: Вариант 3
A2: № | B2: Количество преступлений | C2: Численность населения | D2: Количество осужденных | E2: Количество раскрытых преступлений | F2: Численность мигрантов | H2: Столбец1 | I2: Y | J2: X1 | K2: X2 | L2: X3 | M2: X4
A3: 1 | B3: 60 | C3: 65000 | D3: 35 | E3: 59 | F3: 31 | H3: Корреляции | I3: Столбец 1 | J3: Столбец 2 | K3: Столбец 3 | L3: Столбец 4 | M3: Столбец 5
A4: 2 | B4: 34 | C4: 35500 | D4: 22 | E4: 24 | F4: 22 | H4: Столбец 1 | I4: =CORREL(Лист1!$B$3:$B$26, Лист1!$B$3:$B$26) -> 1
A5: 3 | B5: 56 | C5: 60000 | D5: 32 | E5: 54 | F5: 27 | H5: Столбец 2 | I5: =CORREL(Лист1!$B$3:$B$26, Лист1!$C$3:$C$26) -> 0.87396684 | J5: =CORREL(Лист1!$C$3:$C$26, Лист1!$C$3:$C$26) -> 1
A6: 4 | B6: 30 | C6: 35000 | D6: 16 | E6: 20 | F6: 17 | H6: Столбец 3 | I6: =CORREL(Лист1!$B$3:$B$26, Лист1!$D$3:$D$26) -> 0.70450764 | J6: =CORREL(Лист1!$C$3:$C$26, Лист1!$D$3:$D$26) -> 0.63765727 | K6: =CORREL(Лист1!$D$3:$D$26, Лист1!$D$3:$D$26) -> 1
A7: 5 | B7: 56 | C7: 59000 | D7: 30 | E7: 51 | F7: 25 | H7: Столбец 4 | I7: =CORREL(Лист1!$B$3:$B$26, Лист1!$E$3:$E$26) -> 0.65969181 | J7: =CORREL(Лист1!$C$3:$C$26, Лист1!$E$3:$E$26) -> 0.50740309 | K7: =CORREL(Лист1!$D$3:$D$26, Лист1!$E$3:$E$26) -> 0.57200406 | L7: =CORREL(Лист1!$E$3:$E$26, Лист1!$E$3:$E$26) -> 1
A8: 6 | B8: 34 | C8: 35500 | D8: 33 | E8: 33 | F8: 21 | H8: Столбец 5 | I8: =CORREL(Лист1!$B$3:$B$26, Лист1!$F$3:$F$26) -> 0.90671955 | J8: =CORREL(Лист1!$C$3:$C$26, Лист1!$F$3:$F$26) -> 0.83468052 | K8: =CORREL(Лист1!$D$3:$D$26, Лист1!$F$3:$F$26) -> 0.49925009 | L8: =CORREL(Лист1!$E$3:$E$26, Лист1!$F$3:$F$26) -> 0.3987665 | M8: =CORREL(Лист1!$F$3:$F$26, Лист1!$F$3:$F$26) -> 1
A9: 7 | B9: 80 | C9: 77800 | D9: 41 | E9: 75 | F9: 35
A10: 8 | B10: 48 | C10: 51400 | D10: 27 | E10: 38 | F10: 25
A11: 9 | B11: 28 | C11: 65000 | D11: 35 | E11: 26 | F11: 19
A12: 10 | B12: 58 | C12: 59700 | D12: 31 | E12: 54 | F12: 27
A13: 11 | B13: 68 | C13: 71200 | D13: 37 | E13: 65 | F13: 33
A14: 12 | B14: 38 | C14: 39900 | D14: 23 | E14: 34 | F14: 21
A15: 13 | B15: 32 | C15: 34000 | D15: 17 | E15: 30 | F15: 19
A16: 14 | B16: 18 | C16: 53000 | D16: 35 | E16: 16 | F16: 15
A17: 15 | B17: 52 | C17: 57200 | D17: 31 | E17: 48 | F17: 23
A18: 16 | B18: 78 | C18: 79600 | D18: 40 | E18: 70 | F18: 37
A19: 17 | B19: 98 | C19: 95000 | D19: 53 | E19: 92 | F19: 41
A20: 18 | B20: 96 | C20: 97300 | D20: 51 | E20: 90 | F20: 37
... A26: 24 | B26: 40 | C26: 75000 | D26: 5 | E26: 15 | F26: 27

Sheet Лист2
A1: Вариант 3
A2: № | B2: Количество преступлений | C2: Численность населения | D2: Количество осужденных | E2: Численность мигрантов | G2: Столбец1 | H2: Y | I2: X1 | J2: X2 | K2: X3 | L2: X4 | O2: № | P2: Количество преступлений | Q2: Количество осужденных | R2: Численность мигрантов | S2: ПРОВЕРКА | V2: Y | W2: X2 | X2: X4
A3: п/п | G3: Корреляции | H3: Столбец 1 | I3: Столбец 2 | J3: Столбец 3 | K3: Столбец 4 | L3: Столбец 5 | O3: п/п | U3: Корреляции | V3: Столбец 1 | W3: Столбец 2 | X3: Столбец 3
A4: 1 | B4: 60 | C4: 65000 | D4: 35 | E4: 31 | G4: Столбец 1 | H4: =CORREL(Лист1!$B$3:$B$26, Лист1!$B$3:$B$26) -> 1 | O4: 1 | P4: 60 | Q4: 35 | R4: 31 | S4: =$V$35+$V$36*Q4+$V$37*R4 -> 62.519748 | U4: Столбец 1 | V4: =CORREL(Лист2!$P$4:$P$27, Лист2!$P$4:$P$27) -> 1
A5: 2 | B5: 34 | C5: 35500 | D5: 22 | E5: 22 | G5: Столбец 2 | H5: =CORREL(Лист1!$B$3:$B$26, Лист1!$C$3:$C$26) -> 0.87396684 | I5: =CORREL(Лист1!$C$3:$C$26, Лист1!$C$3:$C$26) -> 1 | O5: 2 | P5: 34 | Q5: 22 | R5: 22 | S5: =$V$35+$V$36*Q5+$V$37*R5 -> 36.768447 | U5: Столбец 2 | V5: =CORREL(Лист2!$P$4:$P$27, Лист2!$Q$4:$Q$27) -> 0.70450764 | W5: =CORREL(Лист2!$Q$4:$Q$27, Лист2!$Q$4:$Q$27) -> 1
A6: 3 | B6: 56 | C6: 60000 | D6: 32 | E6: 27 | G6: Столбец 3 | H6: =CORREL(Лист1!$B$3:$B$26, Лист1!$D$3:$D$26) -> 0.70450764 | I6: =CORREL(Лист1!$C$3:$C$26, Лист1!$D$3:$D$26) -> 0.63765727 | J6: =CORREL(Лист1!$D$3:$D$26, Лист1!$D$3:$D$26) -> 1 | O6: 3 | P6: 56 | Q6: 32 | R6: 27 | S6: =$V$35+$V$36*Q6+$V$37*R6 -> 52.851377 | U6: Столбец 3 | V6: =CORREL(Лист2!$P$4:$P$27, Лист2!$R$4:$R$27) -> 0.90671955 | W6: =CORREL(Лист2!$Q$4:$Q$27, Лист2!$R$4:$R$27) -> 0.49925009 | X6: =CORREL(Лист2!$R$4:$R$27, Лист2!$R$4:$R$27) -> 1
A7: 4 | B7: 30 | C7: 35000 | D7: 16 | E7: 17 | G7: Столбец 4 | H7: =CORREL(Лист1!$B$3:$B$26, Лист1!$E$3:$E$26) -> 0.65969181 | I7: =CORREL(Лист1!$C$3:$C$26, Лист1!$E$3:$E$26) -> 0.50740309 | J7: =CORREL(Лист1!$D$3:$D$26, Лист1!$E$3:$E$26) -> 0.57200406 | K7: =CORREL(Лист1!$E$3:$E$26, Лист1!$E$3:$E$26) -> 1 | O7: 4 | P7: 30 | Q7: 16 | R7: 17 | S7: =$V$35+$V$36*Q7+$V$37*R7 -> 23.243896
A8: 5 | B8: 56 | C8: 59000 | D8: 30 | E8: 25 | G8: Столбец 5 | H8: =CORREL(Лист1!$B$3:$B$26, Лист1!$F$3:$F$26) -> 0.90671955 | I8: =CORREL(Лист1!$C$3:$C$26, Лист1!$F$3:$F$26) -> 0.83468052 | J8: =CORREL(Лист1!$D$3:$D$26, Лист1!$F$3:$F$26) -> 0.49925009 | K8: =CORREL(Лист1!$E$3:$E$26, Лист1!$F$3:$F$26) -> 0.3987665 | L8: =CORREL(Лист1!$F$3:$F$26, Лист1!$F$3:$F$26) -> 1 | O8: 5 | P8: 56 | Q8: 30 | R8: 25 | S8: =$V$35+$V$36*Q8+$V$37*R8 -> 47.697394
A9: 6 | B9: 34 | C9: 35500 | D9: 33 | E9: 21 | O9: 6 | P9: 34 | Q9: 33 | R9: 21 | S9: =$V$35+$V$36*Q9+$V$37*R9 -> 41.866591 | U9: Регрессия
A10: 7 | B10: 80 | C10: 77800 | D10: 41 | E10: 35 | G10: Регрессия | O10: 7 | P10: 80 | Q10: 41 | R10: 35 | S10: =$V$35+$V$36*Q10+$V$37*R10 -> 74.106902 | U10: Регрессионная модель | V10: Линейная
A11: 8 | B11: 48 | C11: 51400 | D11: 27 | E11: 25 | G11: Регрессионная модель | H11: Линейная | O11: 8 | P11: 48 | Q11: 27 | R11: 25 | S11: =$V$35+$V$36*Q11+$V$37*R11 -> 45.778611
A12: 9 | B12: 28 | C12: 65000 | D12: 35 | E12: 19 | G12: Необработанный вывод ЛИНЕЙНАЯ | O12: 9 | P12: 28 | Q12: 35 | R12: 19 | S12: =$V$35+$V$36*Q12+$V$37*R12 -> 39.270986 | U12: Необработанный вывод ЛИНЕЙН
A13: 10 | B13: 58 | C13: 59700 | D13: 31 | E13: 27 | G13: {=LINEST($B$4:$B$27, $C$4:$E$27, 1, 1)} -> 1.6118842 | H13: 0.53825216 | I13: 0.00021405422 | J13: -20.795294 | O13: 10 | P13: 58 | Q13: 31 | R13: 27 | S13: =$V$35+$V$36*Q13+$V$37*R13 -> 52.211782 | U13: {=LINEST($P$4:$P$27, $Q$4:$R$27, 1, 1)} -> 1.9373968 | V13: 0.63959457 | W13: -19.925363
A14: 11 | B14: 68 | C14: 71200 | D14: 37 | E14: 33 | G14: 0.31229316 | H14: 0.1624442 | I14: 0.00015886462 | J14: 5.5247776 | O14: 11 | P14: 68 | Q14: 37 | R14: 33 | S14: =$V$35+$V$36*Q14+$V$37*R14 -> 67.673731 | U14: 0.20170328 | V14: 0.14675191 | W14: 5.592444
A15: 12 | B15: 38 | C15: 39900 | D15: 23 | E15: 21 | G15: 0.91438402 | H15: 7.4413415 | I15: #N/A | J15: #N/A | O15: 12 | P15: 38 | Q15: 23 | R15: 21 | S15: =$V$35+$V$36*Q15+$V$37*R15 -> 35.470645 | U15: 0.90661228 | V15: 7.5844492 | W15: #N/A
A16: 13 | B16: 32 | C16: 34000 | D16: 17 | E16: 19 | G16: 71.200415 | H16: 20 | I16: #N/A | J16: #N/A | O16: 13 | P16: 32 | Q16: 17 | R16: 19 | S16: =$V$35+$V$36*Q16+$V$37*R16 -> 27.758284 | U16: 101.93449 | V16: 21 | W16: #N/A
A17: 14 | B17: 18 | C17: 53000 | D17: 35 | E17: 15 | G17: 11827.862 | H17: 1107.4713 | I17: #N/A | J17: #N/A | O17: 14 | P17: 18 | Q17: 35 | R17: 15 | S17: =$V$35+$V$36*Q17+$V$37*R17 -> 31.521399 | U17: 11727.332 | V17: 1208.0013 | W17: #N/A
A18: 15 | B18: 52 | C18: 57200 | D18: 31 | E18: 23 | O18: 15 | P18: 52 | Q18: 31 | R18: 23 | S18: =$V$35+$V$36*Q18+$V$37*R18 -> 44.462195
A19: 16 | B19: 78 | C19: 79600 | D19: 40 | E19: 37 | G19: Статистика регрессии | O19: 16 | P19: 78 | Q19: 40 | R19: 37 | S19: =$V$35+$V$36*Q19+$V$37*R19 -> 77.342101 | U19: Статистика регрессии
A20: 17 | B20: 98 | C20: 95000 | D20: 53 | E20: 41 | G20: R^2 | H20: =$G$15 -> 0.91438402 | O20: 17 | P20: 98 | Q20: 53 | R20: 41 | S20: =$V$35+$V$36*Q20+$V$37*R20 -> 93.406418 | U20: R^2 | V20: =$U$15 -> 0.90661228
A21: 18 | B21: 96 | C21: 97300 | D21: 51 | E21: 37 | G21: Стандартная ошибка | H21: =$H$15 -> 7.4413415 | O21: 18 | P21: 96 | Q21: 51 | R21: 37 | S21: =$V$35+$V$36*Q21+$V$37*R21 -> 84.377642 | U21: Стандартная ошибка | V21: =$V$15 -> 7.5844492
A22: 19 | B22: 92 | C22: 95400 | D22: 51 | E22: 42 | G22: Число переменных X | H22: =3 -> 3 | O22: 19 | P22: 92 | Q22: 51 | R22: 42 | S22: =$V$35+$V$36*Q22+$V$37*R22 -> 94.064626 | U22: Число переменных X | V22: =2 -> 2
A23: 20 | B23: 94 | C23: 89500 | D23: 52 | E23: 45 | G23: Наблюдения | H23: =24 -> 24 | O23: 20 | P23: 94 | Q23: 52 | R23: 45 | S23: =$V$35+$V$36*Q23+$V$37*R23 -> 100.51641 | U23: Наблюдения | V23: =24 -> 24 | Y23: Первая зависимость:
A24: 21 | B24: 70 | C24: 75700 | D24: 37 | E24: 33 | G24: Скорректированный R^2 | H24: =1 - (1 - $G$15)*($H$23 - 1)/($H$23 - $H$22 - 1) -> 0.90154162 | O24: 21 | P24: 70 | Q24: 37 | R24: 33 | S24: =$V$35+$V$36*Q24+$V$37*R24 -> 67.673731 | U24: Скорректированный R^2 | V24: =1 - (1 - $U$15)*($V$23 - 1)/($V$23 - $V$22 - 1) -> 0.89771821 | Y24: Y = -19,925 + 0,639 * X1 +1,937 * X2, R^2 = 0,906
A25: 22 | B25: 39 | C25: 43400 | D25: 41 | E25: 21 | O25: 22 | P25: 39 | Q25: 41 | R25: 21 | S25: =$V$35+$V$36*Q25+$V$37*R25 -> 46.983347
A26: 23 | B26: 61 | C26: 67700 | D26: 15 | E26: 45 | G26: Дисперсионный анализ (ANOVA) | O26: 23 | P26: 61 | Q26: 15 | R26: 45 | S26: =$V$35+$V$36*Q26+$V$37*R26 -> 76.851411 | U26: Дисперсионный анализ (ANOVA)
A27: 24 | B27: 40 | C27: 75000 | D27: 5 | E27: 27 | H27: df | I27: SS | J27: MS | K27: F | L27: Значимость F | O27: 24 | P27: 40 | Q27: 5 | R27: 27 | S27: =$V$35+$V$36*Q27+$V$37*R27 -> 35.582324 | V27: df | W27: SS | X27: MS | Y27: F | Z27: Значимость F
G28: Регрессия | H28: =$H$22 -> 3 | I28: =$G$17 -> 11827.862 | J28: =$G$17 / $H$28 -> 3942.6207 | K28: =$G$16 -> 71.200415 | L28: =_xlfn.F.DIST.RT($G$16, $H$28, $H$16) -> 7.5191368e-11 | U28: Регрессия | V28: =$V$22 -> 2 | W28: =$U$17 -> 11727.332 | X28: =$U$17 / $V$28 -> 5863.666 | Y28: =$U$16 -> 101.93449 | Z28: =_xlfn.F.DIST.RT($U$16, $V$28, $V$16) -> 1.5418513e-11
G29: Остатки | H29: =$H$16 -> 20 | I29: =$H$17 -> 1107.4713 | J29: =$H$17 / $H$16 -> 55.373563 | U29: Остатки | V29: =$V$16 -> 21 | W29: =$V$17 -> 1208.0013 | X29: =$V$17 / $V$16 -> 57.523869
G30: Итог | H30: =$H$28 + $H$16 -> 23 | I30: =$G$17 + $H$17 -> 12935.333 | U30: Итог | V30: =$V$28 + $V$16 -> 23 | W30: =$U$17 + $V$17 -> 12935.333
G32: Уровень доверия | H32: 0.95 | U32: Уровень доверия | V32: 0.95
H34: Коэффициенты | I34: Стандартная ошибка | J34: t-статистика | K34: P-значение | L34: =COM.MICROSOFT.CONCAT("Нижний ", INT($H$32 * 100), "%") -> #NAME? | M34: =COM.MICROSOFT.CONCAT("Верхний ", INT($H$32 * 100), "%") -> #NAME? | V34: Коэффициенты | W34: Стандартная ошибка | X34: t-статистика | Y34: P-значение | Z34: =COM.MICROSOFT.CONCAT("Нижний ", INT($V$32 * 100), "%") -> #NAME? | AA34: =COM.MICROSOFT.CONCAT("Верхний ", INT($V$32 * 100), "%") -> #NAME?
G35: ="Пересечение" -> Пересечение | H35: {=INDEX($G$13:$J$13, 1, ROW($H$38)+1 - ROW())} -> -20.795294 | I35: {=INDEX($G$14:$J$14, 1, ROW($I$38)+1 - ROW())} -> 5.5247776 | J35: {=$H$35:$H$38 / $I$35:$I$38} -> -3.7640057 | K35: {=TDIST(ABS($J$35:$J$38), $H$16, 2 )} -> 0.0012208404 | L35: {=$H$35:$H$38 - $I$35:$I$38 * _xlfn.T.INV.2T(1 - $H$32, $H$16)} -> -32.319778 | M35: {=$H$35:$H$38 + $I$35:$I$38 * _xlfn.T.INV.2T(1 - $H$32, $H$16)} -> -9.2708102 | U35: ="Пересечение" -> Пересечение | V35: {=INDEX($U$13:$W$13, 1, ROW($V$37)+1 - ROW())} -> -19.925363 | W35: {=INDEX($U$14:$W$14, 1, ROW($W$37)+1 - ROW())} -> 5.592444 | X35: {=$V$35:$V$37 / $W$35:$W$37} -> -3.5629078 | Y35: {=TDIST(ABS($X$35:$X$37), $V$16, 2 )} -> 0.0018379836 | Z35: {=$V$35:$V$37 - $W$35:$W$37 * _xlfn.T.INV.2T(1 - $V$32, $V$16)} -> -31.555487 | AA35: {=$V$35:$V$37 + $W$35:$W$37 * _xlfn.T.INV.2T(1 - $V$32, $V$16)} -> -8.2952385
G36: ="X1" -> X1 | H36: 0.00021405422 | I36: 0.00015886462 | J36: 1.3474002 | K36: 0.19291905 | L36: -0.00011733157 | M36: 0.00054544001 | U36: ="X1" -> X1 | V36: 0.63959457 | W36: 0.14675191 | X36: 4.358339 | Y36: 0.00027580896 | Z36: 0.33440727 | AA36: 0.94478188
G37: ="X2" -> X2 | H37: 0.53825216 | I37: 0.1624442 | J37: 3.3134587 | K37: 0.0034675647 | L37: 0.19939949 | M37: 0.87710483 | U37: ="X2" -> X2 | V37: 1.9373968 | W37: 0.20170328 | X37: 9.6051822 | Y37: 3.9039678e-09 | Z37: 1.5179318 | AA37: 2.3568617
G38: ="X3" -> X3 | H38: 1.6118842 | I38: 0.31229316 | J38: 5.161446 | K38: 4.7474243e-05 | L38: 0.96045214 | M38: 2.2633164
U39: ="X1" -> X1 | V39: ="X2" -> X2 | W39: Прогнозное Y | X39: ="Y" -> Y | Y39: Остатки
G40: ="X1" -> X1 | H40: ="X2" -> X2 | I40: ="X3" -> X3 | J40: Прогнозное Y | K40: ="Y" -> Y | L40: Остатки | U40: {=$Q$4:$R$27} -> 35 | V40: 31 | W40: {=MMULT($U$40:$V$63, $V$36:$V$37) + $V$35} -> 62.519748 | X40: {=$P$4:$P$27} -> 60 | Y40: {=$X$40:$X$63 - $W$40:$W$63} -> -2.5197479
G41: {=$C$4:$E$27} -> 65000 | H41: 35 | I41: 31 | J41: {=MMULT($G$41:$I$64, $H$36:$H$38) + $H$35} -> 61.925467 | K41: {=$B$4:$B$27} -> 60 | L41: {=$K$41:$K$64 - $J$41:$J$64} -> -1.9254672 | U41: 22 | V41: 22 | W41: 36.768447 | X41: 34 | Y41: -2.7684473
G42: 35500 | H42: 22 | I42: 22 | J42: 34.106631 | K42: 34 | L42: -0.10663147 | U42: 32 | V42: 27 | W42: 52.851377 | X42: 56 | Y42: 3.148623
...

Sheet Лист3
A1: Вариант 3
A2: № | B2: Количество преступлений | C2: Количество осужденных | D2: Количество раскрытых преступлений | E2: Численность мигрантов | F2: Столбец1 | H2: Корреляции | I2: Столбец 1 | J2: Столбец 2 | K2: Столбец 3 | L2: Столбец 4
A3: п/п | F3: Проверка | H3: Столбец 1 | I3: =CORREL(Лист3!$B$4:$B$27, Лист3!$B$4:$B$27) -> 1
A4: 1 | B4: 60 | C4: 35 | D4: 59 | E4: 31 | F4: =$I$34+$I$35*C4+$I$36*D4+$I$37*E4 -> 66.173657 | H4: Столбец 2 | I4: =CORREL(Лист3!$B$4:$B$27, Лист3!$C$4:$C$27) -> 0.70450764 | J4: =CORREL(Лист3!$C$4:$C$27, Лист3!$C$4:$C$27) -> 1
A5: 2 | B5: 34 | C5: 22 | D5: 24 | E5: 22 | F5: =$I$34+$I$35*C5+$I$36*D5+$I$37*E5 -> 35.166984 | H5: Столбец 3 | I5: =CORREL(Лист3!$B$4:$B$27, Лист3!$D$4:$D$27) -> 0.65969181 | J5: =CORREL(Лист3!$C$4:$C$27, Лист3!$D$4:$D$27) -> 0.57200406 | K5: =CORREL(Лист3!$D$4:$D$27, Лист3!$D$4:$D$27) -> 1
A6: 3 | B6: 56 | C6: 32 | D6: 54 | E6: 27 | F6: =$I$34+$I$35*C6+$I$36*D6+$I$37*E6 -> 56.323154 | H6: Столбец 4 | I6: =CORREL(Лист3!$B$4:$B$27, Лист3!$E$4:$E$27) -> 0.90671955 | J6: =CORREL(Лист3!$C$4:$C$27, Лист3!$E$4:$E$27) -> 0.49925009 | K6: =CORREL(Лист3!$D$4:$D$27, Лист3!$E$4:$E$27) -> 0.3987665 | L6: =CORREL(Лист3!$E$4:$E$27, Лист3!$E$4:$E$27) -> 1
A7: 4 | B7: 30 | C7: 16 | D7: 20 | E7: 17 | F7: =$I$34+$I$35*C7+$I$36*D7+$I$37*E7 -> 22.584132
A8: 5 | B8: 56 | C8: 30 | D8: 51 | E8: 25 | F8: =$I$34+$I$35*C8+$I$36*D8+$I$37*E8 -> 51.068171 | H8: Регрессия
A9: 6 | B9: 34 | C9: 33 | D9: 33 | E9: 21 | F9: =$I$34+$I$35*C9+$I$36*D9+$I$37*E9 -> 40.048372 | H9: Регрессионная модель | I9: Линейная
A10: 7 | B10: 80 | C10: 41 | D10: 75 | E10: 35 | F10: =$I$34+$I$35*C10+$I$36*D10+$I$37*E10 -> 80.160903
A11: 8 | B11: 48 | C11: 27 | D11: 38 | E11: 25 | F11: =$I$34+$I$35*C11+$I$36*D11+$I$37*E11 -> 46.391841 | H11: Необработанный вывод ЛИНЕЙН
A12: 9 | B12: 28 | C12: 35 | D12: 26 | E12: 19 | F12: =$I$34+$I$35*C12+$I$36*D12+$I$37*E12 -> 35.272896 | H12: {=LINEST($B$4:$B$27, $C$4:$E$27, 1, 1)} -> 1.8331307 | I12: 0.26979372 | J12: 0.38967052 | K12: -20.209693
A13: 10 | B13: 58 | C13: 31 | D13: 54 | E13: 27 | F13: =$I$34+$I$35*C13+$I$36*D13+$I$37*E13 -> 55.933484 | H13: 0.14967042 | I13: 0.061681074 | J13: 0.12174589 | K13: 4.0973218
A14: 11 | B14: 68 | C14: 37 | D14: 65 | E14: 33 | F14: =$I$34+$I$35*C14+$I$36*D14+$I$37*E14 -> 72.238022 | H14: 0.95227038 | I14: 5.5560713 | J14: #N/A | K14: #N/A
A15: 12 | B15: 38 | C15: 23 | D15: 34 | E15: 21 | F15: =$I$34+$I$35*C15+$I$36*D15+$I$37*E15 -> 36.421461 | H15: 133.009 | I15: 20 | J15: #N/A | K15: #N/A
A16: 13 | B16: 32 | C16: 17 | D16: 30 | E16: 19 | F16: =$I$34+$I$35*C16+$I$36*D16+$I$37*E16 -> 29.338001 | H16: 12317.935 | I16: 617.39856 | J16: #N/A | K16: #N/A
A17: 14 | B17: 18 | C17: 35 | D17: 16 | E17: 15 | F17: =$I$34+$I$35*C17+$I$36*D17+$I$37*E17 -> 25.242436
A18: 15 | B18: 52 | C18: 31 | D18: 48 | E18: 23 | F18: =$I$34+$I$35*C18+$I$36*D18+$I$37*E18 -> 46.982199 | H18: Статистика регрессии
A19: 16 | B19: 78 | C19: 40 | D19: 70 | E19: 37 | F19: =$I$34+$I$35*C19+$I$36*D19+$I$37*E19 -> 82.088525 | H19: R^2 | I19: =$H$14 -> 0.95227038
A20: 17 | B20: 98 | C20: 53 | D20: 92 | E20: 41 | F20: =$I$34+$I$35*C20+$I$36*D20+$I$37*E20 -> 100.42223 | H20: Стандартная ошибка | I20: =$I$14 -> 5.5560713
A21: 18 | B21: 96 | C21: 51 | D21: 90 | E21: 37 | F21: =$I$34+$I$35*C21+$I$36*D21+$I$37*E21 -> 91.770775 | H21: Число переменных X | I21: =3 -> 3
A22: 19 | B22: 92 | C22: 51 | D22: 22 | E22: 42 | F22: =$I$34+$I$35*C22+$I$36*D22+$I$37*E22 -> 82.590456 | H22: Наблюдения | I22: =24 -> 24
A23: 20 | B23: 94 | C23: 52 | D23: 35 | E23: 45 | F23: =$I$34+$I$35*C23+$I$36*D23+$I$37*E23 -> 91.986837 | H23: Скорректированный R^2 | I23: =1 - (1 - $H$14)*($I$22 - 1)/($I$22 - $I$21 - 1) -> 0.94511094
A24: 21 | B24: 70 | C24: 37 | D24: 36 | E24: 33 | F24: =$I$34+$I$35*C24+$I$36*D24+$I$37*E24 -> 64.414004
A25: 22 | B25: 39 | C25: 41 | D25: 24 | E25: 21 | F25: =$I$34+$I$35*C25+$I$36*D25+$I$37*E25 -> 40.737593 | H25: Дисперсионный анализ (ANOVA)
A26: 23 | B26: 61 | C26: 15 | D26: 12 | E26: 45 | F26: =$I$34+$I$35*C26+$I$36*D26+$I$37*E26 -> 71.363773 | I26: df | J26: SS | K26: MS | L26: F | M26: Значимость F
A27: 24 | B27: 40 | C27: 5 | D27: 15 | E27: 27 | F27: =$I$34+$I$35*C27+$I$36*D27+$I$37*E27 -> 35.280095 | H27: Регрессия | I27: =$I$21 -> 3 | J27: =$H$16 -> 12317.935 | K27: =$H$16 / $I$27 -> 4105.9783 | L27: =$H$15 -> 133.009 | M27: =_xlfn.F.DIST.RT($H$15, $I$27, $I$15) -> 2.2205687e-13
B28: Y | C28: X2 | D28: X3 | E28: X4 | H28: Остатки | I28: =$I$15 -> 20 | J28: =$I$16 -> 617.39856 | K28: =$I$16 / $I$15 -> 30.869928
H29: Итог | I29: =$I$27 + $I$15 -> 23 | J29: =$H$16 + $I$16 -> 12935.333
H31: Уровень доверия | I31: 0.95
I33: Коэффициенты | J33: Стандартная ошибка | K33: t-статистика | L33: P-значение | M33: =COM.MICROSOFT.CONCAT("Нижний ", INT($I$31 * 100), "%") -> #NAME? | N33: =COM.MICROSOFT.CONCAT("Верхний ", INT($I$31 * 100), "%") -> #NAME?
H34: ="Пересечение" -> Пересечение | I34: {=INDEX($H$12:$K$12, 1, ROW($I$37)+1 - ROW())} -> -20.209693 | J34: {=INDEX($H$13:$K$13, 1, ROW($J$37)+1 - ROW())} -> 4.0973218 | K34: {=$I$34:$I$37 / $J$34:$J$37} -> -4.9324154 | L34: {=TDIST(ABS($K$34:$K$37), $I$15, 2 )} -> 8.0295559e-05 | M34: {=$I$34:$I$37 - $J$34:$J$37 * _xlfn.T.INV.2T(1 - $I$31, $I$15)} -> -28.756557 | N34: {=$I$34:$I$37 + $J$34:$J$37 * _xlfn.T.INV.2T(1 - $I$31, $I$15)} -> -11.66283
H35: ="X1" -> X1 | I35: 0.38967052 | J35: 0.12174589 | K35: 3.2006872 | L35: 0.0044891688 | M35: 0.13571304 | N35: 0.643628
H36: ="X2" -> X2 | I36: 0.26979372 | J36: 0.061681074 | K36: 4.3740113 | L36: 0.00029349035 | M36: 0.14112925 | N36: 0.39845818
H37: ="X3" -> X3 | I37: 1.8331307 | J37: 0.14967042 | K37: 12.247782 | L37: 9.466318e-11 | M37: 1.5209237 | N37: 2.1453378
O39: Y = -20,209 + 0,004 * X2 + 0,0002 *X3 + 9,466^-11 * X4, R^2 = 0,952
